Workbook

Sheet Main
B2: Name | D2: TDP | J2: Price | K2: 221
B3: R100 | C3: Server | D3: 2000 | E3: "at Fab, on schedule for volume production next year. 3D-gen NVLink" | J3: Shares | K3: 24300 | L3: Q225
B4: B100 | C4: Server | D4: 700 | J4: MC | K4: =+K2*K3 -> 5370300
B5: B200 (Blackwell Ultra?) | E5: "has generated 10s of billions in revenue" | J5: Cash | K5: 56791 | L5: Q225
B6: B300 | J6: Debt | K6: 8466 | L6: Q225
B7: H100 | C7: Server | D7: 700 | J7: EV | K7: =+K4-K5+K6 -> 5321975
B8: A100 | C8: Server | D8: 400
B9: V100 | C9: Server | D9: 250-300 | J9: Founded | K9: 1993
B10: 4090 | C10: Consumer | D10: 450
B11: 5090 | C11: Consumer | D11: 575
B12: Clara | C12: Healthcare
B13: Omniverse | C13: Industrial
B14: DRIVE | C14: Autonomous Driving
B15: Quantum | C15: InfiniBand | K15: 2/8/22: Arm deal terminated with SoftBank.
B16: Spectrum | C16: Ethernet | D16: Spectrum-X outperforms Ethernet as networking fabric, will be multi-billion product | K16: 9/13/2020: Announced Arm deal for $40B.
B17: Jetson | K17: 4/27/2020: Mellanox acquisition: $7.1B.
B18: DGX | K18: 2017: first Tensor Core GPU
B19: GeForce NOW | K19: 2012: AlexNet
K20: 2006: CUDA
B21: Wafers | C21: TSMC, Samsung | K21: 1999: invention of the GPU. RIVA TNT2.
B22: Memory | C22: Micron, SK Hynix, Samsung | K22: 1998: Reincorporated in Delaware, filed IPO, RIVA128 product.
B23: Assembly | C23: Hon Hai, Wistron, Fabrinet | K23: 1993: Founded in Santa Clara, California.
K25: 1. Chris Malachowsky (co-founder)
B26: 40% of Data Center revenue was for Inference | K26: 2. Curtis Priem (co-founder)
B27: "Sov AI revenue will reach low double digit billions in FY25" | K27: Christine Hoberg (CFO, charged with fraud).
K28: 26. Jeff Fisher, first sales person
I29: limited 2026 | K29: Mark Allen (left to become CEO of Transmeta)
B31: Rubin | C31: taped out June 2025, next version taping out in September? | F31: MI450 - upcoming AMD chip, Broadcom chip, OpenAI chip
B34: Competition
C35: Ampere Computing acquired by Softbank for $6.5B?!?! Only $16m revenue.

Sheet Model
A1: Main
C2: 43583 | D2: 43674 | E2: 43765 | F2: =+BK2 -> 43856 | G2: 43947 | H2: 44038 | I2: 44129 | J2: 44227 | K2: 44318 | L2: 44409 | M2: 44500 | N2: 44591 | O2: 44682 | P2: =+Q2-91 -> 44773 | Q2: 44864 | R2: 44955 | S2: 45046 | T2: 45135 | U2: 45228 | V2: 45319 | W2: 45410 | X2: =+T2+366 -> 45501 | Y2: 45592 | Z2: 45683 | AA2: =+W2+364 -> 45774 | AB2: =+X2+365 -> 45866 | AC2: =+Y2+365 -> 45957 | AD2: =+Z2+365 -> 46048 | AE2: =+AA2+365 -> 46139 | AF2: =+AB2+365 -> 46231 | AG2: =+AC2+365 -> 46322 | AH2: =+AD2+365 -> 46413 | AL2: 35064 | AM2: 35430 | AN2: 35795 | AO2: 36160 | AP2: 36191 | AQ2: 36555 | AR2: 36919 | AS2: 37283 | AT2: 37646 | AU2: 38011 | AV2: 38382 | AW2: 38746 | AX2: 39110 | AY2: 39474 | AZ2: 39838 | BA2: 40208 | BB2: 40573 | BC2: 40937 | BD2: 41301 | BE2: 41665 | BF2: 42029 | BG2: 42400 | BH2: 42764 | BI2: 43128 | BJ2: 43492 | BK2: 43856 | BL2: 44227 | BM2: 44591 | BN2: =+BO2-365 -> 44955 | BO2: 45320 | BP2: =Z2 -> 45683 | BQ2: =+BP2+365 -> 46048 | BR2: =+BQ2+365 -> 46413 | BS2: =+BR2+365 -> 46778 | BT2: =+BS2+365 -> 47143 | BU2: =+BT2+365 -> 47508 | BV2: =+BU2+365 -> 47873 | BW2: =+BV2+365 -> 48238 | BX2: =+BW2+365 -> 48603 | ... BZ2: =+BY2+365 -> 49333
C3: Q120 | D3: Q220 | E3: Q320 | F3: Q420 | G3: Q121 | H3: Q221 | I3: Q321 | J3: Q421 | K3: Q122 | L3: Q222 | M3: Q322 | N3: Q422 | O3: Q123 | P3: Q223 | Q3: Q323 | R3: Q423 | S3: Q124 | T3: Q224 | U3: Q324 | V3: Q424 | W3: Q125 | X3: Q225 | Y3: Q325 | Z3: Q425 | AA3: Q126 | AB3: Q226 | AC3: Q326 | AD3: Q426 | AE3: Q127 | AF3: Q227 | AG3: Q327 | AH3: Q427 | AL3: FY95 | AM3: FY96 | AN3: FY97 | AO3: FY98 | AP3: FY99 | AQ3: FY00 | AR3: FY01 | AS3: FY02 | AT3: FY03 | AU3: FY04 | AV3: FY05 | AW3: FY06 | AX3: FY07 | AY3: FY08 | AZ3: FY09 | BA3: FY10 | BB3: FY11 | BC3: FY12 | BD3: FY13 | BE3: FY14 | BF3: FY15 | BG3: FY16 | BH3: FY17 | BI3: FY18 | BJ3: FY19 | BK3: FY20 | BL3: FY21 | BM3: FY22 | BN3: FY23 | BO3: FY24 | BP3: FY25 | BQ3: FY26 | BR3: FY27 | BS3: FY28 | BT3: FY29 | BU3: FY30 | BV3: FY31 | BW3: FY32 | BX3: FY33 | BY3: FY34 | BZ3: FY35
B4: Robots | BU4: 5000000 | BV4: =+BU4*2 -> 10000000 | BW4: =+BV4*1.5 -> 15000000 | BX4: =+BW4*1.5 -> 22500000 | BY4: =+BX4*1.5 -> 33750000
B5: Chip Cost | BU5: 50000 | BV5: 50000 | BW5: 50000 | BX5: 50000 | BY5: 50000
B6: Robotics | BU6: =+BU5*BU4/1000000 -> 250000 | BV6: =+BV5*BV4/1000000 -> 500000 | BW6: =+BW5*BW4/1000000 -> 750000 | BX6: =+BX5*BX4/1000000 -> 1125000 | BY6: =+BY5*BY4/1000000 -> 1687500
B8: AGI | BQ8: 40000
B10: Autonomous Vehicles | BU10: 1000000 | BV10: =+BU10*2 -> 2000000 | BW10: =+BV10*2 -> 4000000 | BX10: =+BW10*1.5 -> 6000000 | BY10: =+BX10*1.5 -> 9000000
B11: Chip Cost | BU11: 20000 | BV11: 20000 | BW11: 20000 | BX11: 20000 | BY11: 20000
B12: AV | BU12: =+BU11*BU10/1000000 -> 20000 | BV12: =+BV11*BV10/1000000 -> 40000 | BW12: =+BW11*BW10/1000000 -> 80000 | BX12: =+BX11*BX10/1000000 -> 120000 | BY12: =+BY11*BY10/1000000 -> 180000
B14: Compute & Networking | C14: 694 | D14: 776 | E14: 788 | F14: =+BK14-E14-D14-C14 -> 1021 | G14: 1174 | H14: 1781 | I14: 1939 | J14: =6841-I14-H14-G14 -> 1947 | K14: 2210 | L14: 2600 | M14: 3011 | N14: =11046-M14-L14-K14 -> 3225 | O14: 3672 | P14: 3907 | Q14: 3816 | R14: =15068-Q14-P14-O14 -> 3673 | S14: 4460 | T14: 10402 | U14: 14645 | V14: 17898 | W14: 22675 | X14: 26446 | Y14: 31036 | Z14: 36036 | AA14: 39589 | BK14: 3279 | BL14: 6841 | BM14: 11046 | BN14: =SUM(O14:R14) -> 15068 | BO14: 47405 | BP14: =SUM(W14:Z14) -> 116193
B15: Graphics | C15: 1526 | D15: 1803 | E15: 2226 | F15: =+BK15-E15-D15-C15 -> 2084 | G15: 1906 | H15: 2085 | I15: 2787 | J15: =9834-I15-H15-G15 -> 3056 | K15: 3451 | L15: 3907 | M15: 4092 | N15: =15868-M15-L15-K15 -> 4418 | O15: 4616 | P15: 2797 | Q15: 2115 | R15: =11906-Q15-P15-O15 -> 2378 | S15: 2732 | T15: 3105 | U15: 3475 | V15: 4205 | W15: 3369 | X15: 3594 | Y15: 4046 | Z15: 3295 | AA15: 4473 | BK15: 7639 | BL15: 9834 | BM15: 15868 | BN15: =SUM(O15:R15) -> 11906 | BO15: 13517 | BP15: =SUM(W15:Z15) -> 14304
B17: Other | C17: 99 | D17: 111 | E17: 143 | F17: =+BK17-E17-D17-C17 -> 152 | G17: 138 | H17: 146 | I17: 194 | J17: =631-I17-H17-G17 -> 153 | K17: 327 | L17: 409 | M17: 234 | N17: =1162-M17-L17-K17 -> 192 | O17: 158 | P17: 140 | Q17: 73 | R17: =455-Q17-P17-O17 -> 84 | S17: 77 | T17: 66 | U17: 73 | V17: =306-U17-T17-S17 -> 90 | W17: 78 | X17: 88 | Y17: 97 | Z17: 126 | AA17: 74 | AB17: 173 | AD17: =+Z17*1.4 -> 176.4 | BJ17: 767 | BK17: 505 | BL17: 631 | BM17: 1162 | BN17: =SUM(O17:R17) -> 455 | BO17: =SUM(S17:V17) -> 306 | BP17: =SUM(W17:Z17) -> 389
B18: Visualization | C18: 266 | D18: 291 | E18: 324 | F18: =+BK18-E18-D18-C18 -> 331 | G18: 307 | H18: 203 | I18: 236 | J18: =1053-I18-H18-G18 -> 307 | K18: 372 | L18: 519 | M18: 577 | N18: 643 | O18: 622 | P18: 496 | Q18: 200 | R18: 226 | S18: 295 | T18: 379 | U18: 416 | V18: 463 | W18: 427 | X18: 454 | Y18: 486 | Z18: 511 | AA18: 509 | AB18: 601 | AC18: 760 | AD18: =+Z18*1.4 -> 715.4 | BJ18: 1130 | BK18: 1212 | BL18: 1053 | BM18: 2111 | BN18: =SUM(O18:R18) -> 1544 | BO18: =SUM(S18:V18) -> 1553 | BP18: =SUM(W18:Z18) -> 1878
B19: Automotive | C19: 166 | D19: 209 | E19: 162 | F19: =+BK19-E19-D19-C19 -> 163 | G19: 155 | H19: 111 | I19: 125 | J19: =536-I19-H19-G19 -> 145 | K19: 154 | L19: 152 | M19: 135 | N19: 125 | O19: 138 | P19: 220 | Q19: 251 | R19: 294 | S19: 296 | T19: 253 | U19: 261 | V19: 281 | W19: 329 | X19: 346 | Y19: 449 | Z19: 570 | AA19: 567 | AB19: 586 | AC19: 592 | AD19: =+Z19*1.4 -> 798 | BJ19: 641 | BK19: 700 | BL19: 536 | BM19: 566 | BN19: =SUM(O19:R19) -> 903 | BO19: =SUM(S19:V19) -> 1091 | BP19: =SUM(W19:Z19) -> 1694
B20: Networking | S20: 927 | T20: 1711 | U20: 2606 | V20: 3331 | W20: 3171 | X20: 3668 | Y20: 3127 | Z20: 3024 | AA20: 4957 | AB20: 7252 | BO20: =SUM(S20:V20) -> 8575 | BP20: =SUM(W20:Z20) -> 12990
B21: Compute | S21: 3357 | T21: 8612 | U21: 11908 | V21: 15073 | W21: 19392 | X21: 22604 | Y21: 27644 | Z21: 32556 | AA21: 34155 | AB21: 33844 | BO21: =SUM(S21:V21) -> 38950 | BP21: =SUM(W21:Z21) -> 102196
B22: Data Center | C22: 634 | D22: 655 | E22: 726 | F22: =+BK22-E22-D22-C22 -> 968 | G22: 1141 | H22: 1752 | I22: 1900 | J22: =6696-I22-H22-G22 -> 1903 | K22: 2050 | L22: 2366 | M22: 2936 | N22: 3260 | O22: 3750 | P22: 3806 | Q22: 3833 | R22: 3620 | S22: =+S21+S20 -> 4284 | T22: =+T21+T20 -> 10323 | U22: =+U21+U20 -> 14514 | V22: =47525-U22-T22-S22 -> 18404 | W22: =+W21+W20 -> 22563 | X22: =+X21+X20 -> 26272 | Y22: =+Y21+Y20 -> 30771 | Z22: =+Z21+Z20 -> 35580 | AA22: =+AA21+AA20 -> 39112 | AB22: 41096 | AC22: 51200 | AD22: =+Z22*1.65 -> 58707 | BJ22: 2932 | BK22: 2983 | BL22: 6696 | BM22: =SUM(K22:N22) -> 10612 | BN22: =SUM(O22:R22) -> 15009 | BO22: =+BO21+BO20 -> 47525 | BP22: =+BP21+BP20 -> 115186
B23: Gaming | C23: 1055 | D23: 1313 | E23: 1659 | F23: =+BK23-E23-D23-C23 -> 1491 | G23: 1339 | H23: 1654 | I23: 2271 | J23: =7759-I23-H23-G23 -> 2495 | K23: 2760 | L23: 3061 | M23: 3221 | N23: 3420 | O23: 3620 | P23: 2042 | Q23: 1574 | R23: 1830 | S23: 2240 | T23: 2486 | U23: 2856 | V23: 2865 | W23: 2647 | X23: 2880 | Y23: 3279 | Z23: 2544 | AA23: 3800 | AB23: 4287 | AC23: 4300 | AD23: =+Z23*1.6 -> 4070.4 | BJ23: 6246 | BK23: 5518 | BL23: 7759 | BM23: =SUM(K23:N23) -> 12462 | BN23: =SUM(O23:R23) -> 9066 | BO23: =SUM(S23:V23) -> 10447 | BP23: =SUM(W23:Z23) -> 11350
B24: Revenue | C24: 2220 | D24: =SUM(D17:D23) -> 2579 | E24: =SUM(E17:E23) -> 3014 | F24: =+BK24-E24-D24-C24 -> 3105 | G24: 3080 | H24: =SUM(H17:H23) -> 3866 | I24: =SUM(I17:I23) -> 4726 | J24: 5003 | K24: 5661 | L24: =SUM(L17:L23) -> 6507 | M24: =SUM(M17:M23) -> 7103 | N24: 7643 | O24: =SUM(O17:O23) -> 8288 | P24: =SUM(P17:P23) -> 6704 | Q24: =SUM(Q17:Q23) -> 5931 | R24: 6051 | S24: =+S23+S22+S19+S18+S17 -> 7192 | T24: =+T23+T22+T19+T18+T17 -> 13507 | U24: =+U23+U22+U19+U18+U17 -> 18120 | V24: =+V23+V22+V17+V18+V19 -> 22103 | W24: =+W23+W22+W19+W18+W17 -> 26044 | X24: =+X23+X22+X19+X18+X17 -> 30040 | Y24: =+Y23+Y22+Y19+Y18+Y17 -> 35082 | Z24: =+Z23+Z22+Z19+Z18+Z17 -> 39331 | AA24: =+AA23+AA22+AA19+AA18+AA17 -> 44062 | AB24: =+AB23+AB22+AB19+AB18+AB17 -> 46743 | AC24: 57006 | AD24: 68100 | AE24: 81615 | AF24: 91000 | AG24: 95000 | AH24: 100000 | AL24: 1.182 | AM24: 3.912 | AN24: 29.071 | AO24: 13.3 | AP24: 158.237 | AQ24: 374.505 | AR24: 735.264 | AS24: 1369.471 | AT24: 1909.447 | AU24: 1822.945 | AV24: 2010.033 | AW24: 2375.687 | AX24: 3068.771 | AY24: 4097.86 | AZ24: 3424.859 | BA24: 3326.445 | BB24: 3543.309 | BC24: 3997.93 | BD24: 4280.159 | BE24: 4130 | BF24: 4682 | BG24: 5010 | BH24: 6910 | BI24: 9714 | BJ24: =+BJ23+BJ22+BJ19+BJ18+BJ17 -> 11716 | BK24: =+BK23+BK22+BK19+BK18+BK17 -> 10918 | BL24: =+BL23+BL22+BL19+BL18+BL17 -> 16675 | BM24: =+BM23+BM22+BM19+BM18+BM17 -> 26913 | BN24: =+BN23+BN22+BN19+BN18+BN17 -> 26977 | BO24: =+BO23+BO22+BO19+BO18+BO17 -> 60922 | BP24: =+BP23+BP22+BP19+BP18+BP17 -> 130497 | BQ24: =SUM(AA24:AD24) -> 215911 | BR24: =SUM(AE24:AH24) -> 367615 | BS24: =+BR24*1.7 -> 624945.5 | BT24: =+BS24*1.4 -> 874923.7 | BU24: =+BT24*1.3 -> 1137400.8 | BV24: =+BU24*1.3 -> 1478621.1 | BW24: =+BV24*1.3 -> 1922207.4 | BX24: =+BW24*1.3 -> 2498869.6 | BY24: =+BX24*1.3 -> 3248530.5 | BZ24: =+BY24*1.3 -> 4223089.6
B25: COGS | C25: 924 | D25: 1038 | E25: 1098 | F25: =+BK25-E25-D25-C25 -> 1090 | G25: 1076 | H25: 1591 | I25: 1766 | J25: 1846 | K25: 2032 | L25: 2292 | M25: 2472 | N25: 2644 | O25: 2857 | P25: 3789 | Q25: 2754 | R25: =+BN25-Q25-P25-O25 -> 2218 | S25: 2544 | T25: 4045 | U25: 4720 | V25: 5312 | W25: 5638 | X25: 7466 | Y25: 8926 | Z25: 10608 | AA25: 17394 | AB25: 12890 | AC25: 15157 | AD25: 17034 | AE25: 20458 | AQ25: 141.843 | AR25: 272.879 | AS25: 519.238 | AT25: 1327.271 | AU25: 1294.067 | AV25: 1360.547 | AW25: 1465.654 | AX25: 1768.322 | AY25: 2228.58 | AZ25: 2250.59 | BA25: 2149.522 | BB25: 2134.219 | BC25: 1941.413 | BD25: 2053.816 | BE25: 1862 | BF25: 2083 | BG25: 2199 | BH25: 2847 | BI25: 3892 | BJ25: 4545 | BK25: 4150 | BL25: 6279 | BM25: =SUM(K25:N25) -> 9440 | BN25: 11618 | BO25: =SUM(S25:V25) -> 16621 | BP25: =+BP24-BP26 -> 32638 | BQ25: =+BQ24-BQ26 -> 62475 | BR25: =+BR24-BR26 -> 91903.75 | BS25: =+BS24-BS26 -> 137488.01 | BT25: =+BT24-BT26 -> 192483.21 | BU25: =+BU24-BU26 -> 250228.18 | BV25: =+BV24-BV26 -> 325296.63
B26: Gross Margin | C26: =+C24-C25 -> 1296 | D26: =+D24-D25 -> 1541 | E26: =+E24-E25 -> 1916 | F26: =+F24-F25 -> 2015 | G26: =+G24-G25 -> 2004 | H26: =+H24-H25 -> 2275 | I26: =+I24-I25 -> 2960 | J26: =+J24-J25 -> 3157 | ... S26: =+S24-S25 -> 4648 | T26: =T24-T25 -> 9462 | U26: =+U24-U25 -> 13400 | V26: =+V24-V25 -> 16791 | W26: =+W24-W25 -> 20406 | X26: =+X24-X25 -> 22574 | Y26: =+Y24-Y25 -> 26156 | Z26: =+Z24-Z25 -> 28723 | AA26: =+AA24-AA25 -> 26668 | AB26: =+AB24-AB25 -> 33853 | ... AE26: =+AE24-AE25 -> 61157 | AF26: =+AF24*0.75 -> 68250 | AQ26: =+AQ24-AQ25 -> 232.662 | AR26: =+AR24-AR25 -> 462.385 | AS26: =+AS24-AS25 -> 850.233 | AT26: =+AT24-AT25 -> 582.176 | AU26: =+AU24-AU25 -> 528.878 | AV26: =+AV24-AV25 -> 649.486 | AW26: =+AW24-AW25 -> 910.033 | AX26: =+AX24-AX25 -> 1300.449 | ... BO26: =+BO24-BO25 -> 44301 | BP26: =SUM(W26:Z26) -> 97859 | BQ26: =SUM(AA26:AD26) -> 153436 | BR26: =+BR24*0.75 -> 275711.25 | BS26: =+BS24*0.78 -> 487457.49 | BT26: =+BT24*0.78 -> 682440.49 | BU26: =+BU24*0.78 -> 887172.63 | BV26: =+BV24*0.78 -> 1153324.4
B27: R&D | C27: 674 | D27: 704 | E27: 712 | F27: =+BK27-E27-D27-C27 -> 739 | G27: 735 | H27: 997 | I27: 1047 | J27: 1147 | K27: 1153 | L27: 1245 | M27: 1403 | N27: 1466 | O27: 1618 | P27: 1824 | Q27: 1945 | R27: =+BN27-Q27-P27-O27 -> 1952 | S27: 1875 | T27: 2040 | U27: 2294 | V27: 2465 | W27: 2720 | X27: 3090 | Y27: 3390 | Z27: 3714 | AA27: 3989 | AB27: 4291 | AC27: 4705 | AD27: 5512 | AE27: 6321 | AF27: =+AE27 -> 6321 | AT27: 224.873 | AU27: 269.972 | AV27: 335.104 | AW27: 357.123 | AX27: 553.467 | AY27: 691.637 | AZ27: 855.879 | BA27: 908.851 | BB27: 848.83 | BC27: 1002.605 | BD27: 1147.282 | BE27: 1336 | BF27: 1360 | BG27: 1331 | BH27: 1463 | BI27: 1797 | BJ27: 2376 | BK27: 2829 | BL27: 3924 | BM27: =SUM(K27:N27) -> 5267 | BN27: 7339 | BO27: =SUM(S27:V27) -> 8674 | BP27: =SUM(W27:Z27) -> 12914 | BQ27: =SUM(AA27:AD27) -> 18497 | BR27: =+BQ27*1.2 -> 22196.4 | BS27: =+BR27*1.2 -> 26635.68 | BT27: =+BS27*1.2 -> 31962.816 | BU27: =+BT27*1.2 -> 38355.379 | BV27: =+BU27*1.2 -> 46026.455
B28: SG&A | C28: 264 | D28: 266 | E28: 277 | F28: =+BK28-E28-D28-C28 -> 286 | G28: 293 | H28: 627 | I28: 515 | J28: 503 | K28: 520 | L28: 526 | M28: 557 | N28: 563 | O28: 592 | P28: 592 | Q28: 631 | R28: =+BN28-Q28-P28-O28 -> 625 | S28: 633 | T28: 622 | U28: 689 | V28: 711 | W28: 777 | X28: 842 | Y28: 897 | Z28: 975 | AA28: 1041 | AB28: 1122 | AC28: 1134 | AD28: 1282 | AE28: 1300 | AF28: =+AE28 -> 1300 | AT28: 151.485 | AU28: 165.249 | AV28: 200.789 | AW28: 202.088 | AX28: 293.53 | AY28: 341.297 | AZ28: 362.222 | BA28: 367.017 | BB28: 361.513 | BC28: 405.613 | BD28: 430.822 | BE28: 436 | BF28: 480 | BG28: 602 | BH28: 663 | BI28: 815 | BJ28: 991 | BK28: 1093 | BL28: 1940 | BM28: =SUM(K28:N28) -> 2166 | BN28: 2440 | BO28: =SUM(S28:V28) -> 2655 | BP28: =SUM(W28:Z28) -> 3491 | BQ28: =SUM(AA28:AD28) -> 4579 | BR28: =+BQ28*1.2 -> 5494.8 | BS28: =+BR28*1.2 -> 6593.76 | BT28: =+BS28*1.2 -> 7912.512 | BU28: =+BT28*1.2 -> 9495.0144 | BV28: =+BU28*1.2 -> 11394.017
B29: Operating Expenses | C29: =+C27+C28 -> 938 | D29: =+D27+D28 -> 970 | E29: =+E27+E28 -> 989 | F29: =+F27+F28 -> 1025 | G29: =+G27+G28 -> 1028 | H29: =+H27+H28 -> 1624 | I29: =+I27+I28 -> 1562 | J29: =+J27+J28 -> 1650 | ... AF29: =+AF27+AF28 -> 7621 | AQ29: =+AQ27+AQ28 -> 0 | AR29: =+AR27+AR28 -> 0 | AS29: =+AS27+AS28 -> 0 | AT29: =+AT27+AT28 -> 376.358 | AU29: =+AU27+AU28 -> 435.221 | AV29: =+AV27+AV28 -> 535.893 | AW29: =+AW27+AW28 -> 559.211 | AX29: =+AX27+AX28 -> 846.997 | ... BN29: =+BN27+BN28 -> 9779 | BO29: =SUM(S29:V29) -> 11329 | BP29: =+BP27+BP28 -> 16405 | BQ29: =+BQ27+BQ28 -> 23076 | BR29: =+BR27+BR28 -> 27691.2 | BS29: =+BS27+BS28 -> 33229.44 | BT29: =+BT27+BT28 -> 39875.328 | BU29: =+BU27+BU28 -> 47850.394 | BV29: =+BV27+BV28 -> 57420.472
B30: Operating Income | C30: =+C26-C29 -> 358 | D30: =+D26-D29 -> 571 | E30: =+E26-E29 -> 927 | F30: =+F26-F29 -> 990 | G30: =+G26-G29 -> 976 | H30: =+H26-H29 -> 651 | I30: =+I26-I29 -> 1398 | J30: =+J26-J29 -> 1507 | ... AF30: =+AF26-AF29 -> 60629 | AQ30: =+AQ26-AQ29 -> 232.662 | AR30: =+AR26-AR29 -> 462.385 | AS30: =+AS26-AS29 -> 850.233 | AT30: =+AT26-AT29 -> 205.818 | AU30: =+AU26-AU29 -> 93.657 | AV30: =+AV26-AV29 -> 113.593 | AW30: =+AW26-AW29 -> 350.822 | AX30: =+AX26-AX29 -> 453.452 | ... BV30: =+BV26-BV29 -> 1095903.9
B31: Interest | C31: =44-13 -> 31 | D31: =47-13+1 -> 35 | E31: =45-13 -> 32 | F31: =+BK31-E31-D31-C31 -> 26 | G31: 5 | H31: -42 | I31: =7-53-4 -> -50 | J31: -37 | K31: 88 | L31: -50 | M31: -33 | N31: -105 | O31: =18-68-13 -> -63 | P31: -24 | Q31: 12 | R31: =+BN31-Q31-P31-O31 -> 32 | S31: =150-66-15 -> 69 | T31: =187-65+59 -> 181 | U31: =234-63-66 -> 105 | V31: 491 | W31: =359-64+75 -> 370 | X31: 572 | Y31: =472-61+36 -> 447 | Z31: =511-61+733 -> 1183 | AA31: =515-63-180 -> 272 | AB31: =592-62+2236 -> 2766 | AC31: =624-61 -> 563 | AD31: =568-74 -> 494 | AE31: =+AD31 -> 494 | AF31: =+AE31 -> 494 | AQ31: 23.246 | AR31: 23.246 | AS31: 23.246 | AT31: 23.246 | AU31: 18.561 | AV31: 11.422 | AW31: 20.698 | AX31: 41.82 | AY31: 64.289 | AZ31: =42.859-0.406 -> 42.453 | BA31: 23.115 | BB31: =19.057-3.127-0.508 -> 15.422 | BC31: =19.149-3.089-0.963 -> 15.097 | BD31: =19.908-3.294-2.814 -> 13.8 | BE31: 14 | BF31: 14 | BG31: -4 | BH31: -29 | BI31: -14 | BJ31: 92 | BK31: 124 | BL31: -123 | BM31: =SUM(K31:N31) -> -100 | BN31: =267-262-48 -> -43 | BO31: =SUM(S31:V31) -> 846 | BP31: =SUM(W31:Z31) -> 2572 | BQ31: =SUM(AA31:AD31) -> 4095 | BR31: =+BQ31*1.1 -> 4504.5 | BS31: =+BR31*1.1 -> 4954.95 | BT31: =+BS31*1.1 -> 5450.445 | BU31: =+BT31*1.1 -> 5995.4895 | BV31: =+BU31*1.1 -> 6595.0385
B32: Pretax Income | C32: =+C30+C31 -> 389 | D32: =+D30+D31 -> 606 | E32: =+E30+E31 -> 959 | F32: =+F30+F31 -> 1016 | G32: =+G30+G31 -> 981 | H32: =+H30+H31 -> 609 | I32: =+I30+I31 -> 1348 | J32: =+J30+J31 -> 1470 | ... AF32: =+AF30+AF31 -> 61123 | AQ32: =+AQ30+AQ31 -> 255.908 | AR32: =+AR30+AR31 -> 485.631 | AS32: =+AS30+AS31 -> 873.479 | AT32: =+AT30+AT31 -> 229.064 | AU32: =+AU30+AU31 -> 112.218 | AV32: =+AV30+AV31 -> 125.015 | AW32: =+AW30+AW31 -> 371.52 | AX32: =+AX30+AX31 -> 495.272 | ... BV32: =+BV30+BV31 -> 1102499
B33: Taxes | C33: -5 | D33: 54 | E33: 60 | F33: =+BK33-E33-D33-C33 -> 65 | G33: 64 | H33: -13 | I33: 12 | J33: 13 | K33: 132 | L33: 20 | M33: 174 | N33: -138 | O33: 187 | P33: -181 | Q33: -67 | R33: =+BN33-Q33-P33-O33 -> 61 | S33: 166 | T33: 793 | U33: 1279 | V33: 1821 | W33: 2398 | X33: 2615 | Y33: 3007 | Z33: 3126 | AA33: 3135 | AB33: 4784 | AC33: 6026 | AD33: 7437 | AE33: =+AE32*0.2 -> 10806 | AF33: =+AF32*0.2 -> 12224.6 | AQ33: 59.758 | AR33: 59.758 | AS33: 59.758 | AT33: 59.758 | AU33: 12.254 | AV33: 25.089 | AW33: 55.612 | AX33: 46.35 | AY33: 103.696 | AZ33: 0 | BA33: 0 | BB33: 18.023 | BC33: 82.306 | BD33: 99.503 | BE33: 70 | BF33: 124 | BG33: 129 | BH33: 239 | BI33: 149 | BJ33: -245 | BK33: 174 | BL33: 77 | BM33: =SUM(K33:N33) -> 188 | BN33: 0 | BO33: =SUM(S33:V33) -> 4059 | BP33: =SUM(W33:Z33) -> 11146 | BQ33: =SUM(AA33:AD33) -> 21382 | BR33: =+BR32*0.2 -> 50504.91 | BS33: =+BS32*0.2 -> 91836.6 | BT33: =+BT32*0.2 -> 129603.12 | BU33: =+BU32*0.2 -> 169063.55 | BV33: =+BV32*0.2 -> 220499.8
B34: Net Income | C34: =+C32-C33 -> 394 | D34: =+D32-D33 -> 552 | E34: =+E32-E33 -> 899 | F34: =+F32-F33 -> 951 | G34: =+G32-G33 -> 917 | H34: =+H32-H33 -> 622 | I34: =+I32-I33 -> 1336 | J34: =+J32-J33 -> 1457 | ... S34: =+S32-S33 -> 2043 | T34: =T32-T33 -> 6188 | U34: =U32-U33 -> 9243 | V34: =+V32-V33 -> 12285 | W34: =+W32-W33 -> 14881 | X34: =+X32-X33 -> 16599 | Y34: =+Y32-Y33 -> 19309 | Z34: =+Z32-Z33 -> 22091 | AA34: =+AA32-AA33 -> 18775 | AB34: =+AB32-AB33 -> 26422 | AC34: =+AC32-AC33 -> 30547 | ... AF34: =+AF32-AF33 -> 48898.4 | AQ34: =+AQ32-AQ33 -> 196.15 | AR34: =+AR32-AR33 -> 425.873 | AS34: =+AS32-AS33 -> 813.721 | AT34: =+AT32-AT33 -> 169.306 | AU34: =+AU32-AU33 -> 99.964 | AV34: =+AV32-AV33 -> 99.926 | AW34: =+AW32-AW33 -> 315.908 | AX34: =+AX32-AX33 -> 448.922 | ... BV34: =+BV32-BV33 -> 881999.19 | BW34: =BV34*(1+$BY$44) -> 881999.19 | BX34: =BW34*(1+$BY$44) -> 881999.19 | BY34: =BX34*(1+$BY$44) -> 881999.19 | BZ34: =BY34*(1+$BY$44) -> 881999.19 | CA34: =BZ34*(1+$BY$44) -> 881999.19 | CB34: =CA34*(1+$BY$44) -> 881999.19 | CC34: =CB34*(1+$BY$44) -> 881999.19 | CD34: =CC34*(1+$BY$44) -> 881999.19 | ... FN34: =FM34*(1+$BY$44) -> 881999.19
B35: EPS | C35: =+C34/C36 -> 0.1599026 | D35: =+D34/D36 -> 0.22402597 | E35: =+E34/E36 -> 0.36367314 | F35: =+F34/F36 -> 0.38470874 | G35: =+G34/G36 -> 0.36856913 | H35: =+H34/H36 -> 0.24840256 | I35: =+I34/I36 -> 0.53015873 | J35: =+J34/J36 -> 0.57725832 | ... AF35: =+AF34/AF36 -> 2.001408 | AQ35: =+AQ34/AQ36 -> 1.1648346 | AR35: =+AR34/AR36 -> 2.5290422 | AS35: =+AS34/AS36 -> 4.8322733 | AT35: =+AT34/AT36 -> 1.0054218 | AU35: =+AU34/AU36 -> 0.57880688 | AV35: =+AV34/AV36 -> 0.56596699 | AW35: =+AW34/AW36 -> 0.62055906 | AX35: =+AX34/AX36 -> 0.76444004 | ... BV35: =+BV34/BV36 -> 35.978673
B36: Shares | C36: =616*4 -> 2464 | D36: =616*4 -> 2464 | E36: =618*4 -> 2472 | F36: =+BK36 -> 2472 | G36: =622*4 -> 2488 | H36: 2504 | I36: =630*4 -> 2520 | J36: 2524 | K36: 2528 | L36: 2532 | M36: 2538 | N36: 2545 | O36: 2537 | P36: 2516 | Q36: 2499 | R36: =+BN36 -> 25070 | S36: =2490*10 -> 24900 | T36: 24994 | U36: 2494 | V36: =2490*10 -> 24900 | W36: 2489 | X36: 24848 | Y36: 24774 | Z36: 24706 | AA36: 24611 | AB36: 24532 | AC36: 24483 | AD36: 24432 | AE36: =+AD36 -> 24432 | AF36: =+AE36 -> 24432 | AQ36: 168.393 | AR36: 168.393 | AS36: 168.393 | AT36: 168.393 | AU36: 172.707 | AV36: 176.558 | AW36: 509.07 | AX36: 587.256 | AY36: 606.732 | AZ36: 548.126 | BA36: 549.574 | BB36: 588.684 | BC36: 616.371 | BD36: 624.957 | BE36: 595 | BF36: 563 | BG36: 569 | BH36: 649 | BI36: 632 | BJ36: 625 | BK36: 2472 | BL36: 2510 | BM36: 2535 | BN36: 25070 | BO36: 24940 | BP36: 24804 | BQ36: =AVERAGE(AA36:AD36) -> 24514.5 | BR36: =+BQ36 -> 24514.5 | BS36: =+BR36 -> 24514.5 | BT36: =+BS36 -> 24514.5 | BU36: =+BT36 -> 24514.5 | BV36: =+BU36 -> 24514.5
B38: Revenue y/y | G38: =+G24/C24-1 -> 0.38738739 | H38: =+H24/D24-1 -> 0.49903063 | I38: =+I24/E24-1 -> 0.56801593 | J38: =+J24/F24-1 -> 0.61127214 | K38: =+K24/G24-1 -> 0.83798701 | L38: =+L24/H24-1 -> 0.68313502 | M38: =+M24/I24-1 -> 0.50296234 | N38: =+N24/J24-1 -> 0.52768339 | ... AH38: =+AH24/AD24-1 -> 0.46842878 | AN38: =+AN24/AM24-1 -> 6.4312372 | AO38: =+AO24/AN24-1 -> -0.5424994 | AP38: =+AP24/AO24-1 -> 10.897519 | AQ38: =+AQ24/AP24-1 -> 1.3667347 | AR38: =+AR24/AQ24-1 -> 0.96329555 | AS38: =+AS24/AR24-1 -> 0.86255685 | AT38: =+AT24/AS24-1 -> 0.39429532 | AU38: =+AU24/AT24-1 -> -0.045302122 | ... BV38: =+BV24/BU24-1 -> 0.3
B39: Revenue q/q | D39: =+D24/C24-1 -> 0.16171171 | E39: =+E24/D24-1 -> 0.16867003 | F39: =+F24/E24-1 -> 0.030192435 | G39: =+G24/F24-1 -> -0.0080515298 | H39: =+H24/G24-1 -> 0.25519481 | I39: =+I24/H24-1 -> 0.22245215 | J39: =+J24/I24-1 -> 0.058611934 | K39: =+K24/J24-1 -> 0.13152109 | ... AD39: =+AD24/AC24-1 -> 0.19461109
B40: Data Center q/q | E40: =+E22/D22-1 -> 0.10839695 | F40: =+F22/E22-1 -> 0.33333333 | G40: =+G22/F22-1 -> 0.17871901 | H40: =+H22/G22-1 -> 0.53549518 | I40: =+I22/H22-1 -> 0.084474886 | J40: =+J22/I22-1 -> 0.0015789474 | K40: =+K22/J22-1 -> 0.077246453 | L40: =+L22/K22-1 -> 0.15414634 | ... AD40: =+AD22/AC22-1 -> 0.14662109
B41: Gross Margin | C41: =C26/C24 -> 0.58378378 | D41: =D26/D24 -> 0.59751842 | E41: =E26/E24 -> 0.63570007 | F41: =F26/F24 -> 0.6489533 | G41: =G26/G24 -> 0.65064935 | H41: =H26/H24 -> 0.58846353 | I41: =I26/I24 -> 0.62632247 | J41: =J26/J24 -> 0.63102139 | ... AD41: =AD26/AD24 -> 0.74986784 | AM41: =AM26/AM24 -> 0 | AN41: =AN26/AN24 -> 0 | AO41: =AO26/AO24 -> 0 | AP41: =AP26/AP24 -> 0 | AQ41: =AQ26/AQ24 -> 0.62125205 | AR41: =AR26/AR24 -> 0.62886936 | AS41: =AS26/AS24 -> 0.62084776 | AT41: =AT26/AT24 -> 0.30489246 | ... BV41: =BV26/BV24 -> 0.78
B42: Data Center % | C42: =C22/C24 -> 0.28558559 | D42: =D22/D24 -> 0.25397441 | E42: =E22/E24 -> 0.24087591 | F42: =F22/F24 -> 0.31175523 | G42: =G22/G24 -> 0.37045455 | H42: =H22/H24 -> 0.45318158 | I42: =I22/I24 -> 0.40203132 | J42: =J22/J24 -> 0.38037178 | ... AD42: =AD22/AD24 -> 0.86207048
B44: Net Cash | G44: =+G45-G58 -> 9395 | H44: =+H45-H58 -> 4021 | I44: =+I45-I58 -> 3178 | J44: =+J45-J58 -> 4598 | K44: =+K45-K58 -> 5704 | L44: =+L45-L58 -> 7711 | M44: =+M45-M58 -> 8354 | N44: =+N45-N58 -> 10262 | ... AD44: =+AD45-AD58 -> 76339 | BL44: =+BL45-BL58 -> 4598 | BM44: =+BM45-BM58 -> 10262 | BN44: =+BN45-BN58 -> 2343 | BO44: =+BO45-BO58 -> 16275 | BP44: =+BP45-BP58 -> 34747 | BX44: Terminal | BY44: 0
B45: Cash | G45: =15494+860 -> 16354 | H45: =3274+7707 -> 10981 | I45: =2251+7888 -> 10139 | J45: =847+10714 -> 11561 | K45: =978+11689 -> 12667 | L45: =5628+14026 -> 19654 | M45: =1288+18010 -> 19298 | N45: =1990+19218 -> 21208 | O45: =3887+16451 -> 20338 | P45: =3013+14024 -> 17037 | Q45: =2800+10343 -> 13143 | R45: =3389+9907 -> 13296 | S45: =5079+10241 -> 15320 | T45: =5783+10240 -> 16023 | U45: =5519+12762 -> 18281 | V45: =7280+18704 -> 25984 | W45: =7587+23851 -> 31438 | X45: =8563+26237 -> 34800 | Y45: =9107+29380 -> 38487 | Z45: 43210 | AA45: =15234+38457 -> 53691 | AB45: =11639+45152 -> 56791 | AC45: =11486+49122 -> 60608 | AD45: =51951+10605+22251 -> 84807 | BL45: =+J45 -> 11561 | BM45: =+N45 -> 21208 | BN45: =+R45 -> 13296 | BO45: =+V45 -> 25984 | BP45: =+Z45 -> 43210 | BX45: Discount | BY45: 0.08
B46: AR | G46: 1907 | H46: 2084 | I46: 2546 | J46: 2429 | K46: 3024 | L46: 3586 | M46: 3954 | N46: 4650 | O46: 5438 | P46: 5317 | Q46: 4908 | R46: 3827 | S46: 4080 | T46: 7066 | U46: 8309 | V46: 9999 | W46: 12365 | X46: 14132 | Y46: 17693 | Z46: 23065 | AA46: 22132 | AB46: 27808 | AC46: 33391 | AD46: 38466 | BL46: =+J46 -> 2429 | BM46: =+N46 -> 4650 | BN46: =+R46 -> 3827 | BO46: =+V46 -> 9999 | BP46: =+Z46 -> 23065 | BX46: NPV | BY46: =NPV(BY45,BR34:FO34)+Main!K5-Main!K6+BQ34 -> 9671049.1
...

Sheet Q424 Quarterly Earnings Preview
A1: Main | I1: 0.18063657
G2: GLOBE NEWSWIRE | I2: 0.18071759
I3: 0.18059028
B4: Q4 Consensus | C4: 38250 | E4: Q1 Consensus | F4: 42260 | I4: Stock Price | J4: 132
B5: =+B6-750 -> 35250 | C5: -0.3 | E5: =+E6-1000 -> 38260 | F5: -0.25 | I5: Expected Move | J5: 0.015
B6: =+B7-750 -> 36000 | C6: -0.25 | E6: =+E7-1000 -> 39260 | F6: -0.2 | I6: 132 CALLS | J6: 6.35
B7: =+B8-750 -> 36750 | C7: -0.2 | E7: =+E8-1000 -> 40260 | F7: -0.15 | I7: 132 PUTS | J7: 5.6
B8: =+B9-750 -> 37500 | C8: -0.15 | E8: =+E9-1000 -> 41260 | F8: -0.1 | I8: Premium | J8: =+J7+J6 -> 11.95
B9: =+C4 -> 38250 | C9: -0.1 | E9: 42260 | F9: -0.05 | I9: Loss | J9: =+J5*J4 -> 1.98
B10: =+B9+1000 -> 39250 | C10: -0.05 | E10: =+E9+1000 -> 43260 | F10: 0
B11: =+B10+1000 -> 40250 | C11: 0 | E11: =+E10+1000 -> 44260 | F11: 0.025
B12: =+B11+1000 -> 41250 | C12: 0.025 | E12: =+E11+1000 -> 45260 | F12: 0.05 | I12: 139 CALLS | J12: 3.2
B13: =+B12+1000 -> 42250 | C13: 0.05 | E13: =+E12+1000 -> 46260 | F13: 0.075 | I13: 125 PUTS | J13: 2.92
B14: =+B13+1000 -> 43250 | C14: 0.075 | E14: =+E13+1000 -> 47260 | F14: 0.1 | I14: Premium | J14: =+J12+J13 -> 6.12
B15: =+B14+1000 -> 44250 | C15: 0.1 | E15: =+E14+1000 -> 48260 | F15: 0.105 | I15: Loss | J15: 0

Sheet Q1 Quarterly Earnings Preview
A1: Main
B4: Q1 Revenue | F4: Q2 Guidance
B5: Consensus | C5: 24690 | F5: Consensus | G5: 26820
B6: Low End Guidance | C6: 23520
B7: High End Guidance | C7: 24480
B10: Reactions | C10: 24690 | D10: -0.1 | F10: Reactions | G10: 26820 | H10: -0.1 | K10: =+D10+H10 -> -0.2
C11: 25000 | D11: -0.05 | G11: =G10+500 -> 27320 | H11: -0.05
C12: 25500 | D12: -0.03 | G12: =G11+500 -> 27820 | H12: -0.03
C13: 26000 | D13: -0.01 | G13: =G12+500 -> 28320 | H13: -0.01
C14: 26500 | D14: 0 | G14: =G13+500 -> 28820 | H14: 0
C15: 27000 | D15: 0 | G15: =G14+500 -> 29320 | H15: 0
C16: 27500 | D16: 0.03 | G16: =G15+500 -> 29820 | H16: 0.03
C17: 28000 | D17: 0.05 | G17: =G16+500 -> 30320 | H17: 0.05
C18: 28500 | D18: 0.1 | G18: =G17+500 -> 30820 | H18: 0.1 | K18: =+H18+D18 -> 0.2
B20: Current Price | C20: 954
B21: 955 CALL | C21: 39
B22: 955 PUT | C22: 40
B23: STRADDLE | C23: =C21+C22 -> 79
C24: =C23/C20 -> 0.082809224
